Workbook
Name Óxido_de_cobalto_de_manganeso_y_litio: 'Fórmula 2'!$A$21:$A$23
Name Litio_ferrofosfato: 'Fórmula 2'!$A$17:$A$19
Name Óxido_cobalto_Litio: 'Fórmula 2'!$A$9:$A$11
Name Titanato_de_litio: 'Fórmula 2'!$C$9:$C$11
Name Una_sola_celda: 'Fórmula 2'!$K$5:$K$7
Name Sí: 'Fórmula 2'!$A$26:$A$47
Name Battery_Packaging: 'Fórmula 2'!$E$26:$E$37
Name Polímero_de_litio: 'Fórmula 2'!$C$5:$C$7
Name _18650_: 'Fórmula 2'!$A$5:$A$7
Name Ion_litio: 'Fórmula 2'!$A$13:$A$15
Name Varias_celdas: 'Fórmula 2'!$K$9:$K$12

Sheet Hoja 1
A1: 2970684658 | B1: Precio Mínimo
A2: MLM1411560745 | B2: 699
A3: MLM2096725416 | B3: 490
A4: MLM1945666421 | B4: 170
A5: MLM1976324961 | B5: 799

Sheet ML
A2: Mercado Libre
E3: Retenciónes
A4: ID Secuendario | B4: ID Principal | C4: Producto | D4: Precio OFERTA | E4: Retención IVA | F4: Retención ISR | G4: Costo | H4: Comision | I4: Comision | J4: Envio | K4: Utilidad | L4: ROI | M4: Ingreso x venta
B5: 608098925 | C5: Elevation Training Mask 2.0 Mascara Elevacion Mma Crossfit | D5: 399 | E5: =D5*0.069 -> 27.531 | F5: =D5*0.0215 -> 8.5785 | G5: 273.43 | H5: 0.1 | I5: =H5*D5 -> 39.9 | J5: 67.5 | K5: =D5-G5-I5-J5-E5-F5 -> -17.9395 | L5: =K5/G5 -> -0.065609114 | M5: =D5-E5-F5-I5-J5 -> 255.4905
B6: 682638186 | C6: Faja Chaleco Reductora Para Hombres Gym Sauna Neopreno | D6: 269 | E6: =D6*0.069 -> 18.561 | F6: =D6*0.0215 -> 5.7835 | G6: 92.61 | H6: 0.1 | I6: =H6*D6 -> 26.9 | K6: =D6-G6-I6-J6-E6-F6 -> 125.1455 | L6: =K6/G6 -> 1.3513174 | M6: =D6-E6-F6-I6-J6 -> 217.7555
B7: 3679281894 | D7: 4299 | E7: =D7*0.069 -> 296.631 | F7: =D7*0.0215 -> 92.4285 | G7: 3305.02 | H7: 0.145 | I7: =H7*D7 -> 623.355 | J7: 65 | K7: =D7-G7-I7-J7-E7-F7 -> -83.4345 | L7: =K7/G7 -> -0.025244779 | M7: =D7-E7-F7-I7-J7 -> 3221.5855
B8: 2910333802 | C8: Faja Chaleco Reductora Para Hombres Gym Sauna Neopreno | D8: 159 | E8: =D8*0.069 -> 10.971 | F8: =D8*0.0215 -> 3.4185 | G8: 92.61 | H8: 0.15 | I8: =H8*D8 -> 23.85 | J8: 30 | K8: =D8-G8-I8-J8-E8-F8 -> -1.8495 | L8: =K8/G8 -> -0.019970845 | M8: =D8-E8-F8-I8-J8 -> 90.7605
B9: 648656572 | C9: Brazalete Antebrazo Para Celular Giratorio 360 Grados | D9: 290 | E9: =D9*0.069 -> 20.01 | F9: =D9*0.0215 -> 6.235 | G9: 84.13 | H9: 0.1 | I9: =H9*D9 -> 29 | J9: 62.5 | K9: =D9-G9-I9-J9-E9-F9 -> 88.125 | L9: =K9/G9 -> 1.047486 | M9: =D9-E9-F9-I9-J9 -> 172.255
B10: 741040525 | C10: Playera Camiseta Pesas Gym Fisicoculturista Gimnasio | D10: 199 | E10: =D10*0.069 -> 13.731 | F10: =D10*0.0215 -> 4.2785 | G10: 99 | H10: 0.19 | I10: =H10*D10 -> 37.81 | J10: 37 | K10: =D10-G10-I10-J10-E10-F10 -> 7.1805 | L10: =K10/G10 -> 0.072530303 | M10: =D10-E10-F10-I10-J10 -> 106.1805
B11: 612395579 | C11: Máscara De Entrenamiento Training Mask 3.0 Para Correr Mask | D11: 799 | E11: =D11*0.069 -> 55.131 | F11: =D11*0.0215 -> 17.1785 | G11: 370.08 | H11: 0.1 | I11: =H11*D11 -> 79.9 | J11: 102.5 | K11: =D11-G11-I11-J11-E11-F11 -> 174.2105 | L11: =K11/G11 -> 0.47073741 | M11: =D11-E11-F11-I11-J11 -> 544.2905
B12: 832811198 | C12: Bandas Para Ejercicio De Resistencia De Cadera Yoga Bandas | D12: 199 | E12: =D12*0.069 -> 13.731 | F12: =D12*0.0215 -> 4.2785 | G12: 123.47 | H12: 0.1 | I12: =H12*D12 -> 19.9 | K12: =D12-G12-I12-J12-E12-F12 -> 37.6205 | L12: =K12/G12 -> 0.30469345 | M12: =D12-E12-F12-I12-J12 -> 161.0905
B13: 1347125652 | C13: Bocina Xiaomi Mi Compact Bluetooth Speaker 2 Portátil White | D13: 201 | E13: =D13*0.069 -> 13.869 | F13: =D13*0.0215 -> 4.3215 | G13: 120.87 | H13: 0.1 | I13: =H13*D13 -> 20.1 | K13: =D13-G13-I13-J13-E13-F13 -> 41.8395 | L13: =K13/G13 -> 0.34615289 | M13: =D13-E13-F13-I13-J13 -> 162.7095
B14: 663293921 | C14: Gorro Bufanda Cuello Unisex Invierno Frío Envío Gratis | D14: 157 | E14: =D14*0.069 -> 10.833 | F14: =D14*0.0215 -> 3.3755 | G14: 99.43 | H14: 0.1 | I14: =H14*D14 -> 15.7 | K14: =D14-G14-I14-J14-E14-F14 -> 27.6615 | L14: =K14/G14 -> 0.27820074 | M14: =D14-E14-F14-I14-J14 -> 127.0915
B15: 1309775400 | C15: 2 Clavija Convertidor Europeo A Americano Adaptador Cargador | D15: 43.64 | E15: =D15*0.069 -> 3.01116 | F15: =D15*0.0215 -> 0.93826 | G15: 10 | H15: 0.1 | I15: =H15*D15 -> 4.364 | K15: =D15-G15-I15-J15-E15-F15 -> 25.32658 | L15: =K15/G15 -> 2.532658 | M15: =D15-E15-F15-I15-J15 -> 35.32658
B16: 659287446 | C16: Chamarra Táctica Militar Contra Lluvia Campamentos Esdy | D16: 482 | E16: =D16*0.069 -> 33.258 | F16: =D16*0.0215 -> 10.363 | G16: 402.33 | H16: 0.1 | I16: =H16*D16 -> 48.2 | J16: 84 | K16: =D16-G16-I16-J16-E16-F16 -> -96.151 | L16: =K16/G16 -> -0.23898541 | M16: =D16-E16-F16-I16-J16 -> 306.179
B17: 1661515275 | C17: Bocina Inteligente Xiaomi Mi Smart Speaker L09g Con Asistente Virtual Google Assistant Blanca 100v/240v | D17: 707 | E17: =D17*0.069 -> 48.783 | F17: =D17*0.0215 -> 15.2005 | G17: 428.26 | H17: 0.1 | I17: =H17*D17 -> 70.7 | J17: 75 | K17: =D17-G17-I17-J17-E17-F17 -> 69.0565 | L17: =K17/G17 -> 0.16124901 | M17: =D17-E17-F17-I17-J17 -> 497.3165
B18: 921639303 | C18: Chamarra De Borrega Para Hombre Chaqueta Casual Moda | D18: 623 | E18: =D18*0.069 -> 42.987 | F18: =D18*0.0215 -> 13.3945 | G18: 410.8 | H18: 0.1 | I18: =H18*D18 -> 62.3 | J18: 91.5 | K18: =D18-G18-I18-J18-E18-F18 -> 2.0185 | L18: =K18/G18 -> 0.0049135833 | M18: =D18-E18-F18-I18-J18 -> 412.8185
B19: 598780987 | C19: Arnés Para Cuello Lastrado Head Harness Iq Sports | D19: 329 | E19: =D19*0.069 -> 22.701 | F19: =D19*0.0215 -> 7.0735 | G19: 115 | H19: 0.1 | I19: =H19*D19 -> 32.9 | J19: 62.5 | K19: =D19-G19-I19-J19-E19-F19 -> 88.8255 | L19: =K19/G19 -> 0.77239565 | M19: =D19-E19-F19-I19-J19 -> 203.8255
B20: 960650439 | C20: Audífonos In-ear Inalámbricos Xiaomi Redmi Airdots 2 Negro | D20: 279 | E20: =D20*0.069 -> 19.251 | F20: =D20*0.0215 -> 5.9985 | G20: 73.67 | H20: 0.15 | I20: =H20*D20+30 -> 71.85 | K20: =D20-G20-I20-J20-E20-F20 -> 108.2305 | L20: =K20/G20 -> 1.4691258 | M20: =D20-E20-F20-I20-J20 -> 181.9005
B21: 937333053 | C21: Sweater Cuello Alto Moda Hombre Invierno Tortuga Wimbledon | D21: 499 | E21: =D21*0.069 -> 34.431 | F21: =D21*0.0215 -> 10.7285 | G21: 236.9 | H21: 0.1 | I21: =H21*D21 -> 49.9 | J21: 102.5 | K21: =D21-G21-I21-J21-E21-F21 -> 64.5405 | L21: =K21/G21 -> 0.27243774 | M21: =D21-E21-F21-I21-J21 -> 301.4405
B22: 1304177930 | C22: Chamarra Vini Piel De Hombre Slim Fit Estilo Biker Cazadora | D22: 379 | E22: =D22*0.069 -> 26.151 | F22: =D22*0.0215 -> 8.1485 | G22: 294.92 | H22: 0.1 | I22: =H22*D22 -> 37.9 | J22: 72.5 | K22: =D22-G22-I22-J22-E22-F22 -> -60.6195 | L22: =K22/G22 -> -0.20554557 | M22: =D22-E22-F22-I22-J22 -> 234.3005
B23: 773727066 | C23: Trx Training Ligas Bandas De Suspensión Multifuncional Casa | D23: 549 | E23: =D23*0.069 -> 37.881 | F23: =D23*0.0215 -> 11.8035 | G23: 382 | H23: 0.1 | I23: =H23*D23 -> 54.9 | J23: 67.5 | K23: =D23-G23-I23-J23-E23-F23 -> -5.0845 | L23: =K23/G23 -> -0.013310209 | M23: =D23-E23-F23-I23-J23 -> 376.9155
B24: 673924123 | C24: Training Mask Mascara Elevación Mma Crossfit 4 Niveles | D24: 469 | E24: =D24*0.069 -> 32.361 | F24: =D24*0.0215 -> 10.0835 | G24: 290 | H24: 0.1 | I24: =H24*D24 -> 46.9 | J24: 78 | K24: =D24-G24-I24-J24-E24-F24 -> 11.6555 | L24: =K24/G24 -> 0.040191379 | M24: =D24-E24-F24-I24-J24 -> 301.6555
B25: 614600530 | C25: Chaleco Peso Crossfit Lastrado 27 Libras Correr | D25: 899 | E25: =D25*0.069 -> 62.031 | F25: =D25*0.0215 -> 19.3285 | G25: 450 | H25: 0.1 | I25: =H25*D25 -> 89.9 | J25: 151 | K25: =D25-G25-I25-J25-E25-F25 -> 126.7405 | L25: =K25/G25 -> 0.28164556 | M25: =D25-E25-F25-I25-J25 -> 576.7405
B26: 814514678 | C26: Corrector De Postura De Espalda Con Imanes | D26: 299 | E26: =D26*0.069 -> 20.631 | F26: =D26*0.0215 -> 6.4285 | G26: 175 | H26: 0.1 | I26: =H26*D26 -> 29.9 | J26: 78 | K26: =D26-G26-I26-J26-E26-F26 -> -10.9595 | L26: =K26/G26 -> -0.062625714 | M26: =D26-E26-F26-I26-J26 -> 164.0405
B27: 862256648 | C27: Falda Deportiva Short Licra Correr Gym Sexy Mujer Fitness | D27: 399 | E27: =D27*0.069 -> 27.531 | F27: =D27*0.0215 -> 8.5785 | G27: 239 | H27: 0.1 | I27: =H27*D27 -> 39.9 | J27: 72 | K27: =D27-G27-I27-J27-E27-F27 -> 11.9905 | L27: =K27/G27 -> 0.050169456 | M27: =D27-E27-F27-I27-J27 -> 250.9905
B28: 832509572 | C28: Licra Short Para Ciclismo Con Pad Anatómico Y Gel En Piernas | D28: 299 | E28: =D28*0.069 -> 20.631 | F28: =D28*0.0215 -> 6.4285 | G28: 123 | H28: 0.1 | I28: =H28*D28 -> 29.9 | J28: 78 | K28: =D28-G28-I28-J28-E28-F28 -> 41.0405 | L28: =K28/G28 -> 0.3336626 | M28: =D28-E28-F28-I28-J28 -> 164.0405
B29: 619668470 | C29: 4 Polainas 2 Kg Cada Una 8 Kg Lastradas Envío Gratis | D29: 499 | E29: =D29*0.069 -> 34.431 | F29: =D29*0.0215 -> 10.7285 | H29: 0.1 | I29: =H29*D29 -> 49.9 | J29: 116 | K29: =D29-G29-I29-J29-E29-F29 -> 287.9405 | L29: =K29/G29 -> #DIV/0! | M29: =D29-E29-F29-I29-J29 -> 287.9405
B30: 963461182 | C30: Control Joystick Razer Wolverine Ultimate Negro | D30: 1955 | E30: =D30*0.069 -> 134.895 | F30: =D30*0.0215 -> 42.0325 | G30: 1296.4 | H30: 0.1 | I30: =H30*D30 -> 195.5 | J30: 62.5 | K30: =D30-G30-I30-J30-E30-F30 -> 223.6725 | L30: =K30/G30 -> 0.17253355 | M30: =D30-E30-F30-I30-J30 -> 1520.0725
B31: 1410430551 | C31: Xiaomi Mi Watch 1.39 Caja De Polímero Reforzado Con Fibra De Vidrio Black, Malla Black De Tpu Xmwtcl02 | D31: 2599 | E31: =D31*0.069 -> 179.331 | F31: =D31*0.0215 -> 55.8785 | G31: 1800 | H31: 0.1 | I31: =H31*D31 -> 259.9 | J31: 62.5 | K31: =D31-G31-I31-J31-E31-F31 -> 241.3905 | L31: =K31/G31 -> 0.13410583 | M31: =D31-E31-F31-I31-J31 -> 2041.3905
B32: 956690848 | C32: Xiaomi Mi Watch Lite 1.4 Caja Navy Blue, Malla Navy Blue De Tpu Redmiwt02 | D32: 784 | E32: =D32*0.069 -> 54.096 | F32: =D32*0.0215 -> 16.856 | G32: 611.91 | H32: 0.1 | I32: =H32*D32 -> 78.4 | J32: 62 | K32: =D32-G32-I32-J32-E32-F32 -> -39.262 | L32: =K32/G32 -> -0.064163031 | M32: =D32-E32-F32-I32-J32 -> 572.648
B33: 1372361536 | C33: Audífonos In-ear Inalámbricos Xiaomi Mi Earphones 2 Basic Blanco | D33: 412 | E33: =D33*0.069 -> 28.428 | F33: =D33*0.0215 -> 8.858 | G33: 274.26 | H33: 0.1 | I33: =H33*D33 -> 41.2 | J33: 67.5 | K33: =D33-G33-I33-J33-E33-F33 -> -8.246 | L33: =K33/G33 -> -0.03006636 | M33: =D33-E33-F33-I33-J33 -> 266.014
B34: 1330421284 | C34: Audífonos In-ear Mi True Wireless Earbud Basic S | D34: 499 | E34: =D34*0.069 -> 34.431 | F34: =D34*0.0215 -> 10.7285 | G34: 127 | H34: 0.1 | I34: =H34*D34 -> 49.9 | J34: 116 | K34: =D34-G34-I34-J34-E34-F34 -> 160.9405 | L34: =K34/G34 -> 1.267248 | M34: =D34-E34-F34-I34-J34 -> 287.9405
B35: 1330452732 | C35: Apple AirPods Pro - Blanco | D35: 5999 | E35: =D35*0.069 -> 413.931 | F35: =D35*0.0215 -> 128.9785 | G35: 627.34 | H35: 0.1 | I35: =H35*D35 -> 599.9 | J35: 57 | K35: =D35-G35-I35-J35-E35-F35 -> 4171.8505 | L35: =K35/G35 -> 6.650063 | M35: =D35-E35-F35-I35-J35 -> 4799.1905
B36: 927019108 | C36: Aspiradora Trapeadora Robot Xiaomi Mi Robot Vacuum-mop Essential Blanca 100v/240v | D36: 3700 | E36: =D36*0.069 -> 255.3 | F36: =D36*0.0215 -> 79.55 | G36: 2800 | H36: 0.1 | I36: =H36*D36 -> 370 | J36: 130 | K36: =D36-G36-I36-J36-E36-F36 -> 65.15 | L36: =K36/G36 -> 0.023267857 | M36: =D36-E36-F36-I36-J36 -> 2865.15
B37: 1375071912 | C37: Cámara Vigilancia Xiaomi Mi 360° Camera 1080p Vision Nocturn | D37: 539 | E37: =D37*0.069 -> 37.191 | F37: =D37*0.0215 -> 11.5885 | G37: 317.24 | H37: 0.1 | I37: =H37*D37 -> 53.9 | J37: 91.5 | K37: =D37-G37-I37-J37-E37-F37 -> 27.5805 | L37: =K37/G37 -> 0.086938911 | M37: =D37-E37-F37-I37-J37 -> 344.8205
B38: 1314430762 | C38: Audífonos In-ear Inalámbricos Jbl Under Armour Ua Project Rock Black | D38: 1199 | E38: =D38*0.069 -> 82.731 | F38: =D38*0.0215 -> 25.7785 | G38: 566.17 | H38: 0.1 | I38: =H38*D38 -> 119.9 | J38: 60 | K38: =D38-G38-I38-J38-E38-F38 -> 344.4205 | L38: =K38/G38 -> 0.60833407 | M38: =D38-E38-F38-I38-J38 -> 910.5905
B39: 1353124983 | C39: Funda Silicona Compatible Con iPhone 7/8 X/s Max iPhone 11 | D39: 99 | E39: =D39*0.069 -> 6.831 | F39: =D39*0.0215 -> 2.1285 | G39: 62 | H39: 0.1 | I39: =H39*D39 -> 9.9 | K39: =D39-G39-I39-J39-E39-F39 -> 18.1405 | L39: =K39/G39 -> 0.29258871 | M39: =D39-E39-F39-I39-J39 -> 80.1405
A40: 1372355175 | B40: 1372871257 | C40: Router Xiaomi Mi 4a Blanco 110v/240v | D40: 399 | E40: =D40*0.069 -> 27.531 | F40: =D40*0.0215 -> 8.5785 | G40: 250 | H40: 0.1 | I40: =H40*D40 -> 39.9 | J40: 58.4 | K40: =D40-G40-I40-J40-E40-F40 -> 14.5905 | L40: =K40/G40 -> 0.058362 | M40: =D40-E40-F40-I40-J40 -> 264.5905
B41: 960684889 | C41: Guantes Venum Boxeo Contender White, Black, Silver, Boxing | D41: 989 | E41: =D41*0.069 -> 68.241 | F41: =D41*0.0215 -> 21.2635 | G41: 692.02 | H41: 0.1 | I41: =H41*D41 -> 98.9 | J41: 102 | K41: =D41-G41-I41-J41-E41-F41 -> 6.5755 | L41: =K41/G41 -> 0.009501893 | M41: =D41-E41-F41-I41-J41 -> 698.5955
...

Sheet AMZ
A2: Amazon
A3: Producto | B3: ASIN | C3: SKU | D3: Precio de venta | E3: Estatus | F3: Retenciones | H3: Costo | I3: Comision | J3: Comison | K3: Sin iVA | L3: Envio | M3: Utilidad | N3: ROI | O3: Ingreso x venta
A4: Mi Box | B4: B07KB1KLYN | D4: 1199 | F4: =D4*0.069 -> 82.731 | H4: 849.99 | I4: 0.1 | J4: =I4*D4 -> 119.9 | K4: =J4/1.16 -> 103.36207 | L4: 66.04 | M4: =D4-H4-J4-L4-F4-G4 -> 80.339 | N4: =M4/H4 -> 0.094517583
A5: Mi Band 5 | B5: B089NS9JW2 | D5: 532 | F5: =D5*0.069 -> 36.708 | H5: 400 | I5: 0.15 | J5: =I5*D5 -> 79.8 | K5: =J5/1.16 -> 68.793103 | M5: =D5-H5-J5-L5-F5-G5 -> 15.492 | N5: =M5/H5 -> 0.03873
A6: Mi Projector 2 | B6: B08RMX5XVR | F6: =D6*0.069 -> 0 | H6: 8350.23 | I6: 0.1 | J6: =I6*D6 -> 0 | K6: =J6/1.16 -> 0 | M6: =D6-H6-J6-L6-F6-G6 -> -8350.23 | N6: =M6/H6 -> -1
A7: Roku 4k+ | B7: B0916TKFF2 | D7: 859 | F7: =D7*0.069 -> 59.271 | H7: 629.71 | I7: 0.1 | J7: =I7*D7 -> 85.9 | K7: =J7/1.16 -> 74.051724 | M7: =D7-H7-J7-L7-F7-G7 -> 84.119 | N7: =M7/H7 -> 0.13358371
A8: Roku exprees | B8: B07WVFCVJN | D8: 699 | F8: =D8*0.069 -> 48.231 | H8: 472.46 | I8: 0.1 | J8: =I8*D8 -> 69.9 | K8: =J8/1.16 -> 60.258621 | M8: =D8-H8-J8-L8-F8-G8 -> 108.409 | N8: =M8/H8 -> 0.22945646
A9: Aura | B9: B0C4FYKW24 | D9: 4399 | F9: =D9*0.069 -> 303.531 | H9: 3488.27 | I9: 0.1 | J9: =I9*D9 -> 439.9 | K9: =J9/1.16 -> 379.22414 | L9: 109.85 | M9: =D9-H9-J9-L9-F9-G9 -> 57.449 | N9: =M9/H9 -> 0.016469195
A10: Roku4k streaming | B10: B09BKCDXZC | D10: 770 | F10: =D10*0.069 -> 53.13 | H10: 623.52 | I10: 0.1 | J10: =I10*D10 -> 77 | K10: =J10/1.16 -> 66.37931 | L10: 66.04 | M10: =D10-H10-J10-L10-F10-G10 -> -49.69 | N10: =M10/H10 -> -0.079692712
A11: Scooter essential | B11: B089NR5WZ8 | D11: 7999 | F11: =D11*0.069 -> 551.931 | H11: 5200 | I11: 0.15 | J11: =I11*D11 -> 1199.85 | K11: =J11/1.16 -> 1034.3534 | L11: 400 | M11: =D11-H11-J11-L11-F11-G11 -> 647.219 | N11: =M11/H11 -> 0.12446519
A12: Clavija | B12: B091V6V2CL | D12: 99 | F12: =D12*0.069 -> 6.831 | H12: 9 | I12: 0.15 | J12: =I12*D12 -> 14.85 | K12: =J12/1.16 -> 12.801724 | M12: =D12-H12-J12-L12-F12-G12 -> 68.319 | N12: =M12/H12 -> 7.591
A13: Aspiradora Mop 1C | B13: B086W5Y1CG | D13: 6399 | F13: =D13*0.069 -> 441.531 | H13: 4500 | I13: 0.15 | J13: =I13*D13 -> 959.85 | K13: =J13/1.16 -> 827.4569 | M13: =D13-H13-J13-L13-F13-G13 -> 497.619 | N13: =M13/H13 -> 0.110582
A14: Earphones Blancos | B14: B08BRGH7S3 | D14: 545 | F14: =D14*0.069 -> 37.605 | H14: 347.85 | I14: 0.15 | J14: =I14*D14 -> 81.75 | K14: =J14/1.16 -> 70.474138 | M14: =D14-H14-J14-L14-F14-G14 -> 77.795 | N14: =M14/H14 -> 0.22364525
A15: Buds 3 PRO | B15: B09C3W56FC | D15: 759 | F15: =D15*0.069 -> 52.371 | H15: 530.77 | I15: 0.1 | J15: =I15*D15 -> 75.9 | K15: =J15/1.16 -> 65.431034 | M15: =D15-H15-J15-L15-F15-G15 -> 99.959 | N15: =M15/H15 -> 0.18832828
A16: Router 4A | B16: B085G5CDY7 | D16: 419 | F16: =D16*0.069 -> 28.911 | H16: 270.12 | I16: 0.1 | J16: =I16*D16 -> 41.9 | K16: =J16/1.16 -> 36.12069 | M16: =D16-H16-J16-L16-F16-G16 -> 78.069 | N16: =M16/H16 -> 0.28901599
A17: Router 4c | B17: B09HSV3JZ5 | C17: B09HSV3JZ5-new4c | D17: 339 | F17: =D17*0.069 -> 23.391 | H17: 200 | I17: 0.1 | J17: =I17*D17 -> 33.9 | K17: =J17/1.16 -> 29.224138 | L17: 67.45 | M17: =D17-H17-J17-L17-F17-G17 -> 14.259 | N17: =M17/H17 -> 0.071295
A18: Tablet ONN | B18: B09FBZ4D9T | D18: 1599 | F18: =D18*0.069 -> 110.331 | H18: 1021.82 | I18: 0.1 | J18: =I18*D18 -> 159.9 | K18: =J18/1.16 -> 137.84483 | M18: =D18-H18-J18-L18-F18-G18 -> 306.949 | N18: =M18/H18 -> 0.30039439
A19: Mi Speaker 2 | B19: B07RD3FNTN | D19: 232 | F19: =D19*0.069 -> 16.008 | H19: 179.45 | I19: 0.1 | J19: =I19*D19 -> 23.2 | K19: =J19/1.16 -> 20 | M19: =D19-H19-J19-L19-F19-G19 -> 13.342 | N19: =M19/H19 -> 0.074349401
A20: Razer Tournament | B20: B075M47H3H | F20: =D20*0.069 -> 0 | I20: 0.1 | J20: =I20*D20 -> 0 | K20: =J20/1.16 -> 0 | M20: =D20-H20-J20-L20-F20-G20 -> 0 | N20: =M20/H20 -> #DIV/0!
A21: Mi Band 6 | B21: B091G3FLL7 | D21: 799 | F21: =D21*0.069 -> 55.131 | H21: 519 | I21: 0.15 | J21: =I21*D21 -> 119.85 | K21: =J21/1.16 -> 103.31897 | M21: =D21-H21-J21-L21-F21-G21 -> 105.019 | N21: =M21/H21 -> 0.20234875
A22: Buds 3 lite | B22: B09NQKCQWS | D22: 479 | F22: =D22*0.069 -> 33.051 | H22: 163.64 | I22: 0.15 | J22: =I22*D22 -> 71.85 | K22: =J22/1.16 -> 61.939655 | M22: =D22-H22-J22-L22-F22-G22 -> 210.459 | N22: =M22/H22 -> 1.2861098
A23: Aspiradora Mop P | B23: B085BP7ZC5 | D23: 8499 | F23: =D23*0.069 -> 586.431 | H23: 6161.78 | I23: 0.15 | J23: =I23*D23 -> 1274.85 | K23: =J23/1.16 -> 1099.0086 | M23: =D23-H23-J23-L23-F23-G23 -> 475.939 | N23: =M23/H23 -> 0.077240505
A24: Watch S1 | B24: B09S8BKKHB | D24: 1977 | F24: =D24*0.069 -> 136.413 | H24: 1183.46 | I24: 0.16 | J24: =I24*D24 -> 316.32 | K24: =J24/1.16 -> 272.68966 | M24: =D24-H24-J24-L24-F24-G24 -> 340.807 | N24: =M24/H24 -> 0.28797509
A25: Buds 3 | B25: B09J4T4JF5 | D25: 439 | F25: =D25*0.069 -> 30.291 | H25: 274.78 | I25: 0.15 | J25: =I25*D25 -> 65.85 | K25: =J25/1.16 -> 56.767241 | M25: =D25-H25-J25-L25-F25-G25 -> 68.079 | N25: =M25/H25 -> 0.24775821
A26: Repetidor Xiaomi | B26: B0762SH6WG | D26: 329 | F26: =D26*0.069 -> 22.701 | H26: 229.36 | I26: 0.1 | J26: =I26*D26 -> 32.9 | K26: =J26/1.16 -> 28.362069 | M26: =D26-H26-J26-L26-F26-G26 -> 44.039 | N26: =M26/H26 -> 0.1920082
A27: Repetidor Xiaomi | B27: B084WT4WWK | D27: 299 | F27: =D27*0.069 -> 20.631 | H27: 180 | I27: 0.1 | J27: =I27*D27 -> 29.9 | K27: =J27/1.16 -> 25.775862 | L27: 69 | M27: =D27-H27-J27-L27-F27-G27 -> -0.531 | N27: =M27/H27 -> -0.00295
A28: Cargador Xiaomi Tipo c 20W | B28: B0969PK3SG | D28: 359 | F28: =D28*0.069 -> 24.771 | H28: 207.48 | I28: 0.15 | J28: =I28*D28 -> 53.85 | K28: =J28/1.16 -> 46.422414 | M28: =D28-H28-J28-L28-F28-G28 -> 72.899 | N28: =M28/H28 -> 0.35135435
A29: Xiaomi Pad 5 256 gb | B29: B09JBZQG49 | D29: 10599 | F29: =D29*0.069 -> 731.331 | H29: 8689.0468 | I29: 0.1 | J29: =I29*D29 -> 1059.9 | K29: =J29/1.16 -> 913.7069 | M29: =D29-H29-J29-L29-F29-G29 -> 118.7222 | N29: =M29/H29 -> 0.013663432
A30: Xiaomi Pad 5 128 gb | B30: B09JBZP2WR | D30: 9590 | F30: =D30*0.069 -> 661.71 | H30: 7847.8477 | I30: 0.1 | J30: =I30*D30 -> 959 | K30: =J30/1.16 -> 826.72414 | M30: =D30-H30-J30-L30-F30-G30 -> 121.4423 | N30: =M30/H30 -> 0.015474599
A31: Mi watch | B31: B08P5J7KGH | D31: 2599 | F31: =D31*0.069 -> 179.331 | H31: 1488 | I31: 0.15 | J31: =I31*D31 -> 389.85 | K31: =J31/1.16 -> 336.07759 | M31: =D31-H31-J31-L31-F31-G31 -> 541.819 | N31: =M31/H31 -> 0.36412567
A32: Camara 360 | B32: B093C8S6B1 | D32: 599 | F32: =D32*0.069 -> 41.331 | H32: 391 | I32: 0.15 | J32: =I32*D32 -> 89.85 | K32: =J32/1.16 -> 77.456897 | L32: 66.04 | M32: =D32-H32-J32-L32-F32-G32 -> 10.779 | N32: =M32/H32 -> 0.027567775
A33: Camara 360 | B33: B07P12T1G3 | D33: 999 | F33: =D33*0.069 -> 68.931 | H33: 340 | I33: 0.15 | J33: =I33*D33 -> 149.85 | K33: =J33/1.16 -> 129.18103 | M33: =D33-H33-J33-L33-F33-G33 -> 440.219 | N33: =M33/H33 -> 1.2947618
A34: Xiaomi Smart Camera C300 White bhr6540gl… | B34: B0B6PG6S81 | D34: 1199 | F34: =D34*0.069 -> 82.731 | H34: 789 | I34: 0.15 | J34: =I34*D34 -> 179.85 | K34: =J34/1.16 -> 155.0431 | L34: 67 | M34: =D34-H34-J34-L34-F34-G34 -> 80.419 | N34: =M34/H34 -> 0.10192522
A35: Mop 2 nueva 1c | B35: B09R8WM46V | D35: 5999 | F35: =D35*0.069 -> 413.931 | H35: 4324.97 | I35: 0.15 | J35: =I35*D35 -> 899.85 | K35: =J35/1.16 -> 775.73276 | M35: =D35-H35-J35-L35-F35-G35 -> 360.249 | N35: =M35/H35 -> 0.083295144
A36: Pilas AAA | B36: B00VQVVOTS | D36: 149 | F36: =D36*0.069 -> 10.281 | H36: 65.54 | I36: 0.15 | J36: =I36*D36 -> 22.35 | K36: =J36/1.16 -> 19.267241 | M36: =D36-H36-J36-L36-F36-G36 -> 50.829 | N36: =M36/H36 -> 0.77554165
A37: Pilas AA | B37: B00V7FQUOM | D37: 172 | F37: =D37*0.069 -> 11.868 | H37: 82.59 | I37: 0.15 | J37: =I37*D37 -> 25.8 | K37: =J37/1.16 -> 22.241379 | M37: =D37-H37-J37-L37-F37-G37 -> 51.742 | N37: =M37/H37 -> 0.62649231
A38: Cargador de Pilas | B38: B078XL37LQ | D38: 259 | F38: =D38*0.069 -> 17.871 | H38: 149.64 | I38: 0.15 | J38: =I38*D38 -> 38.85 | K38: =J38/1.16 -> 33.491379 | M38: =D38-H38-J38-L38-F38-G38 -> 52.639 | N38: =M38/H38 -> 0.35177092
A39: Aspiradora Xiaomi Mop 2 Lite | B39: B09TFYRVG9 | D39: 4999 | F39: =D39*0.069 -> 344.931 | H39: 3675.8 | I39: 0.15 | J39: =I39*D39 -> 749.85 | K39: =J39/1.16 -> 646.42241 | M39: =D39-H39-J39-L39-F39-G39 -> 228.419 | N39: =M39/H39 -> 0.062141303
A40: Acer Chromebook Spin 311, CP311-2H-C7QD, 4 GB, 64 GB, Plateado | B40: B08NTP5RTN | D40: 5699 | F40: =D40*0.069 -> 393.231 | H40: 4048.08 | I40: 0.1 | J40: =I40*D40 -> 569.9 | K40: =J40/1.16 -> 491.2931 | M40: =D40-H40-J40-L40-F40-G40 -> 687.789 | N40: =M40/H40 -> 0.16990499
A41: Samsund Laptop | B41: B07XQQTVS3 | D41: 4499 | F41: =D41*0.069 -> 310.431 | H41: 3596.22 | I41: 0.1 | J41: =I41*D41 -> 449.9 | K41: =J41/1.16 -> 387.84483 | M41: =D41-H41-J41-L41-F41-G41 -> 142.449 | N41: =M41/H41 -> 0.039610758
...

Sheet Hoja 18
A1: 3750270288 | B1: BL710WM | H1: ASIN | I1: Referral Fee Nivel 1
A2: 3750335524 | H2: B0D3P8ZP21 | I2: 0.099
A3: 2503498501 | H3: B07VGT69TG | I3: 0.099
A4: 3826490638 | B4: BL610 | H4: B0F7SJ9MT8 | I4: 0.098934
A5: 4317244286 | H5: B0FFN6NRTZ | I5: 0.083292
A6: 2347926527 | B6: BN401 | H6: B003NF40OG | I6: 0.099
A7: 2517923221 | B7: BN300 | H7: B0CBBP8BQX | I7: 0.079134
A8: 2340764625 | B8: BN801 | H8: B0DDN2JNSV | I8: 0.098802
A9: 4165765140 | H9: B0B6FHKKHP | I9: 0.099
B10: BN400 | H10: B0D9H19PBL | I10: 0.098274
A11: 3793815784 | B11: ES601 | H11: B0F3JWFL56 | I11: 0.065934
B12: SL401 | H12: B09FM6PDHP | I12: 0.099
A13: 3793946112 | B13: JC151 | H13: B0F58Q4CM9 | I13: 0.065868
A14: 3793946198 | B14: TB401LAA | H14: B0DSG3MMDZ | I14: 0.065934
A15: 3795266826 | B15: CM401 | H15: B0DNV41CHB | I15: 0.066
B16: QB3000SS | H16: B085FVKSMC | I16: 0.066
A17: 2359818339 | B17: HD435LAA Shark Flex Style Blanco | H17: B0FN7VLZCH | I17: 0.065736
B18: HD442BP Shark Malibu Pink | H18: B0FKBDT8FR | I18: 0.065934
A19: 2359684899 | B19: HD450TL Shark Flex Style Teal | H19: B0CF7LY4XZ | I19: 0.066
A20: 2386343109 | B20: BN701LAA | H20: B0CZRMRQ3Y | I20: 0.065802
A21: 3750659954 | H21: B09HGGV5R5 | I21: 0.098934
A22: 2426721105 | H22: B09XSDMT4F | I22: 0.070488
A23: 4016269482 | B23: CT800 | H23: B0FN7XC2J7 | I23: 0.066
A24: 2386376891 | B24: FW312LAA | H24: B0CF7GCG6F | I24: 0.065934
B25: IX141LAA | H25: B0DK6ZC5ZC | I25: 0.096558
A26: 2475112999 | B26: CT610 | H26: B0D9YYQ7X9 | I26: 0.098934
A27: 3550149464 | B27: NC301LAA | H27: B0BHT7NX51 | I27: 0.099
A28: 4016385322
A29: 4095291968 | B29: Cl305A
A30: 4139036224 | B30: CO905KS
A31: 4180187602 | B31: SS101
A32: 2475353115 | B32: FA222
A33: 4180157156 | B33: BL660
A34: 2475086533 | B34: TB201LAA
A35: 2475035161 | B35: BL480
A36: 4330026978 | B36: CN501COLAA
B37: WV201CO
A38: 2492015425 | B38: TB400LAA
B39: IZ492HLAA
A40: 2492030151 | B40: FA200
...

Sheet Remates AMZ 
A4: Producto | B4: ASIN | C4: Precio de venta | E4: Costo | F4: Comision | G4: Comison IVa | H4: Envio | I4: Utilidad | J4: ROI
A5: Mi Box | B5: B07KB1KLYN | C5: 1130 | E5: 849.99 | F5: 0.1 | G5: =F5*C5 -> 113 | H5: 68.324 | I5: =C5-E5-G5-H5 -> 98.686 | J5: =I5/E5 -> 0.11610254
A6: Mi Band 5 | B6: B089NS9JW2 | C6: 532 | E6: 400 | F6: 0.15 | G6: =F6*C6 -> 79.8 | H6: 68.324 | I6: =C6-E6-G6-H6 -> -16.124 | J6: =I6/E6 -> -0.04031
A7: Mi Projector 2 | B7: B08RMX5XVR | E7: 8350.23 | F7: 0.1 | G7: =F7*C7 -> 0 | H7: 54.56 | I7: =C7-E7-G7-H7 -> -8404.79 | J7: =I7/E7 -> -1.006534
A8: Roku 4k+ | B8: B0916TKFF2 | C8: 859 | E8: 629.71 | F8: 0.1 | G8: =F8*C8 -> 85.9 | H8: 67.164 | I8: =C8-E8-G8-H8 -> 76.226 | J8: =I8/E8 -> 0.12104937
A9: Roku exprees | B9: B07WVFCVJN | C9: 699 | E9: 472.46 | F9: 0.1 | G9: =F9*C9 -> 69.9 | H9: 67.164 | I9: =C9-E9-G9-H9 -> 89.476 | J9: =I9/E9 -> 0.18938323
A10: Roku4k streaming | B10: B09BKCDXZC | C10: 878 | E10: 622 | F10: 0.15 | G10: =F10*C10 -> 131.7 | H10: =66*1.16 -> 76.56 | I10: =C10-E10-G10-H10 -> 47.74 | J10: =I10/E10 -> 0.076752412
A11: Scooter essential | B11: B089NR5WZ8 | C11: 8299 | E11: 6199.42 | F11: 0.15 | G11: =F11*C11 -> 1244.85 | H11: 254.04 | I11: =C11-E11-G11-H11 -> 600.69 | J11: =I11/E11 -> 0.096894548
A12: Clavija | B12: B091V6V2CL | C12: 99 | E12: 9 | F12: 0.15 | G12: =F12*C12 -> 14.85 | H12: 67.28 | I12: =C12-E12-G12-H12 -> 7.87 | J12: =I12/E12 -> 0.87444444
A13: Aspiradora Mop 1C | B13: B086W5Y1CG | C13: 6399 | E13: 4500 | F13: 0.15 | G13: =F13*C13 -> 959.85 | H13: 101.31 | I13: =C13-E13-G13-H13 -> 837.84 | J13: =I13/E13 -> 0.18618667
A14: Earphones Blancos | B14: B08BRGH7S3 | C14: 545 | E14: 347.85 | F14: 0.15 | G14: =F14*C14 -> 81.75 | H14: 67.164 | I14: =C14-E14-G14-H14 -> 48.236 | J14: =I14/E14 -> 0.13866897
A15: Buds 3 PRO | B15: B09C3W56FC | C15: 759 | E15: 530.77 | F15: 0.1 | G15: =F15*C15 -> 75.9 | H15: 67.6164 | I15: =C15-E15-G15-H15 -> 84.7136 | J15: =I15/E15 -> 0.1596051
A16: Router 4A | B16: B085G5CDY7 | C16: 419 | E16: 270.12 | F16: 0.1 | G16: =F16*C16 -> 41.9 | H16: 78.88 | I16: =C16-E16-G16-H16 -> 28.1 | J16: =I16/E16 -> 0.10402784
A17: Router 4c | B17: B09HSV3JZ5 | C17: 359 | E17: 200 | F17: 0.15 | G17: =F17*C17 -> 53.85 | H17: 78.88 | I17: =C17-E17-G17-H17 -> 26.27 | J17: =I17/E17 -> 0.13135
A18: Tablet ONN | B18: B09FBZ4D9T | C18: 1599 | E18: 1021.82 | F18: 0.1 | G18: =F18*C18 -> 159.9 | H18: 65.58 | I18: =C18-E18-G18-H18 -> 351.7 | J18: =I18/E18 -> 0.34418978
A19: Mi Speaker 2 | B19: B07RD3FNTN | C19: 232 | E19: 179.45 | F19: 0.1 | G19: =F19*C19 -> 23.2 | I19: =C19-E19-G19-H19 -> 29.35 | J19: =I19/E19 -> 0.16355531
A20: Razer Tournament | B20: B075M47H3H | F20: 0.1 | G20: =F20*C20 -> 0 | H20: 210.32 | I20: =C20-E20-G20-H20 -> -210.32 | J20: =I20/E20 -> #DIV/0!
A21: Mi Band 6 | B21: B091G3FLL7 | C21: 799 | E21: 519 | F21: 0.15 | G21: =F21*C21 -> 119.85 | H21: 62.64 | I21: =C21-E21-G21-H21 -> 97.51 | J21: =I21/E21 -> 0.18788054
A22: Buds 3 lite | B22: B09NQKCQWS | C22: 479 | E22: 163.64 | F22: 0.15 | G22: =F22*C22 -> 71.85 | H22: 67.6164 | I22: =C22-E22-G22-H22 -> 175.8936 | J22: =I22/E22 -> 1.0748814
A23: Aspiradora Mop P | B23: B085BP7ZC5 | C23: 8499 | E23: 6161.78 | F23: 0.15 | G23: =F23*C23 -> 1274.85 | H23: 125.28 | I23: =C23-E23-G23-H23 -> 937.09 | J23: =I23/E23 -> 0.15208105
A24: Watch S1 | B24: B09S8BKKHB | C24: 1977 | E24: 1183.46 | F24: 0.16 | G24: =F24*C24 -> 316.32 | H24: 67.28 | I24: =C24-E24-G24-H24 -> 409.94 | J24: =I24/E24 -> 0.34639109
A25: Buds 3 | B25: B09J4T4JF5 | C25: 439 | E25: 274.78 | F25: 0.15 | G25: =F25*C25 -> 65.85 | H25: 67.28 | I25: =C25-E25-G25-H25 -> 31.09 | J25: =I25/E25 -> 0.11314506
A26: Repetidor Xiaomi | B26: B0762SH6WG | C26: 329 | E26: 229.36 | F26: 0.1 | G26: =F26*C26 -> 32.9 | H26: 58 | I26: =C26-E26-G26-H26 -> 8.74 | J26: =I26/E26 -> 0.038106034
A27: Repetidor Xiaomi | B27: B084WT4WWK | C27: 359 | E27: 229.36 | F27: 0.1 | G27: =F27*C27 -> 35.9 | H27: 58 | I27: =C27-E27-G27-H27 -> 35.74 | J27: =I27/E27 -> 0.1558249
A28: Cargador Xiaomi Tipo c 20W | B28: B0969PK3SG | C28: 359 | E28: 207.48 | F28: 0.15 | G28: =F28*C28 -> 53.85 | H28: 70.76 | I28: =C28-E28-G28-H28 -> 26.91 | J28: =I28/E28 -> 0.12969925
A29: Xiaomi Pad 5 256 gb | B29: B09JBZQG49 | C29: 10599 | E29: 8689.0468 | F29: 0.1 | G29: =F29*C29 -> 1059.9 | H29: 69.71 | I29: =C29-E29-G29-H29 -> 780.3432 | J29: =I29/E29 -> 0.089807688
A30: Xiaomi Pad 5 128 gb | B30: B09JBZP2WR | C30: 9590 | E30: 7847.8477 | F30: 0.1 | G30: =F30*C30 -> 959 | H30: 69.71 | I30: =C30-E30-G30-H30 -> 713.4423 | J30: =I30/E30 -> 0.090909295
A31: Mi watch | B31: B08P5J7KGH | C31: 2599 | E31: 1488 | F31: 0.15 | G31: =F31*C31 -> 389.85 | H31: 58 | I31: =C31-E31-G31-H31 -> 663.15 | J31: =I31/E31 -> 0.44566532
A32: Camara 360 | B32: B093C8S6B1 | C32: 599 | E32: 340 | F32: 0.15 | G32: =F32*C32 -> 89.85 | H32: 70.76 | I32: =C32-E32-G32-H32 -> 98.39 | J32: =I32/E32 -> 0.28938235
... A45: Haylou gt7 | B45: B09HXSW5ZX | C45: 499 | E45: 320.13 | F45: 0.15 | G45: =F45*C45 -> 74.85 | H45: 67.6164 | I45: =C45-E45-G45-H45 -> 36.4036 | J45: =I45/E45 -> 0.11371505
A46: Clavija Blanca | B46: B07FFBD8XP | C46: 107 | E46: =10.17*2 -> #ERROR! | F46: 0.15 | G46: =F46*C46 -> 16.05 | H46: 67.6164 | I46: =C46-E46-G46-H46 -> #ERROR! | J46: =I46/E46 -> #ERROR!
A47: Speaker azul | B47: B08MKQ6DXJ | C47: 795 | E47: 470.69 | F47: 0.1 | G47: =F47*C47 -> 79.5 | H47: 75.4 | I47: =C47-E47-G47-H47 -> 169.41 | J47: =I47/E47 -> 0.35991842
A48: Monitor Bar | B48: B08W2C5W59 | C48: 1011 | E48: 550.03 | F48: 0.1 | G48: =F48*C48 -> 101.1 | H48: 87 | I48: =C48-E48-G48-H48 -> 272.87 | J48: =I48/E48 -> 0.49610021
A49: Samsung Tab A8 | B49: B08QQTQNDC | C49: 4299 | E49: 3177.28 | F49: 0.1 | G49: =F49*C49 -> 429.9 | H49: 67.6164 | I49: =C49-E49-G49-H49 -> 624.2036 | J49: =I49/E49 -> 0.19645848
A50: Tv stick | B50: B09LPTSRMH | C50: 849 | E50: 614.8 | F50: 0.15 | G50: =F50*C50 -> 127.35 | H50: 68.092 | I50: =C50-E50-G50-H50 -> 38.758 | J50: =I50/E50 -> 0.06304164
A51: aspiradora Mini Xiaomi | B51: B08MPQQJHQ | C51: 899 | E51: 523.64 | F51: 0.15 | G51: =F51*C51 -> 134.85 | H51: 172.84 | I51: =C51-E51-G51-H51 -> 67.67 | J51: =I51/E51 -> 0.12923001
A52: Scooter S1 | B52: B076KKX4BC | C52: 10599 | E52: 6325 | F52: 0.15 | G52: =F52*C52 -> 1589.85 | H52: 261 | I52: =C52-E52-G52-H52 -> 2423.15 | J52: =I52/E52 -> 0.38310672
A53: Teclado Cyrosa V2 | B53: B089KLHYG3 | C53: 1199 | E53: 845.234 | F53: 0.1 | G53: =F53*C53 -> 119.9 | H53: 102.4048 | I53: =C53-E53-G53-H53 -> 131.4612 | J53: =I53/E53 -> 0.15553231
A54: Audifono Blackshark V2 | E54: 997.6 | G54: =F54*C54 -> 0
A55: Teclado Ornata V2 | B55: B086TKHRSN | C55: 1799 | E55: 1305.3712 | F55: 0.15 | G55: =F55*C55 -> 269.85 | H55: 102.08 | I55: =C55-E55-G55-H55 -> 121.6988 | J55: =I55/E55 -> 0.093229267
...

Sheet Analisis Reembolso Parcial 
A1: Catalogo | B1: ID | C1: Producto | D1: Precio OFERTA | E1: Precio Minimo | F1: Costo | G1: Comision | H1: Comision | I1: Envio | J1: Utilidad | K1: ROI | L1: Estatus
A2: Catalogo | B2: 2019878109 | C2: Audífonos In-ear Inalámbricos Skullcandy Indy Black | D2: 539 | E2: 499 | F2: 308.83 | G2: 0.1 | H2: =G2*D2 -> 53.9 | I2: 62.5 | J2: =D2-F2-H2-I2 -> 113.77 | K2: =J2/F2 -> 0.36839038 | L2: Activa
A4: Si se concretara la venta
A5: Utilidad esperada de esta venta | B5: =J2 -> 113.77
A6: ROI | B6: =K2 -> 0.36839038
A8: Descuento al comprador | B8: 0.2
A9: Si aplicamos Reembolso | D9: No aplicamos Reembolso
A10: Precio Venta | B10: =D2 -> 539 | D10: Precio de venta | E10: =D2 -> 539 | F10: Si lo vendemos al mismo precio
A11: Si aplicamos %20 de reembolso | B11: =B10*B8 -> 107.8 | D11: Devolucion | E11: 125 | F11: Quedamos a dever por aceptarlo
A12: Fee de Ml | B12: =(1-B8)*H2 -> 43.12 | D12: Nueva comision de envio | E12: =H2 -> 53.9
A13: Envio | B13: =I2 -> 62.5
A14: Costo del producto | B14: =F2 -> 308.83 | D14: Nuevo Fee | E14: =I2 -> 62.5
A15: Utilidad | B15: =B10-B11-B12-B13-B14 -> 16.75 | D15: Costo | E15: =F2 -> 308.83
D16: Utilidad | E16: =E10-E11-E12-E14-E15 -> -11.23 | F16: Si no lo regresa

Sheet Fórmula
A1: ¿El producto incluye baterías o es una batería en sí mismo? | B1: Composición química / tipo de la celda de la batería | C1: Embalaje de la batería | D1: Vatios/hora | E1: Potencial de derrame | I1: ¿El producto incluye baterías o es una batería en sí mismo? | J1: Composición química / tipo de la celda de la batería | K1: Embalaje de la batería | L1: Número de celdas | M1: Vatios/hora | N1: Potencial de derrame | O1: Statut de validation des détails
A2: Sí | B2: _18650_ | C2: En el aparato | D2: WH <= 100 | E2: Derramable | F2: _18650_ | H2: =I2&J2&K2&L2&M2&N2 -> No | I2: No | O2: Completo
A3: No | B3: Óxido_cobalto_Litio | C3: Con el equipo | D3: 101 - 300 WH | E3: No derramable | F3: Óxido_cobalto_Litio | H3: =I3&J3&K3&L3&M3&N3 -> SíAlcalina | I3: Sí | J3: Alcalina | O3: Completo
B4: Ion_litio | C4: Independiente | D4: WH > 300 | F4: Ion_litio | H4: =I4&J4&K4&L4&M4&N4 -> SíNíquel_metal_hidruro | I4: Sí | J4: Níquel_metal_hidruro | O4: Completo
B5: Litio_ferrofosfato | F5: Litio_ferrofosfato | H5: =I5&J5&K5&L5&M5&N5 -> SíNíquel_cadmio | I5: Sí | J5: Níquel_cadmio | O5: Completo
B6: Óxido_de_cobalto_de_manganeso_y_litio | F6: Óxido_de_cobalto_de_manganeso_y_litio | H6: =I6&J6&K6&L6&M6&N6 -> SíZinc_carbono | I6: Sí | J6: Zinc_carbono | O6: Completo
B7: Polímero_de_litio | F7: Polímero_de_litio | H7: =I7&J7&K7&L7&M7&N7 -> SíZinc_aire | I7: Sí | J7: Zinc_aire | O7: Completo
B8: Titanato_de_litio | F8: Titanato_de_litio | H8: =I8&J8&K8&L8&M8&N8 -> SíÓxido_de_plata | I8: Sí | J8: Óxido_de_plata | O8: Completo
B9: Litio_Metal | F9: Litio_Metal | H9: =I9&J9&K9&L9&M9&N9 -> SíIon_litioEn el aparato | I9: Sí | J9: Ion_litio | K9: En el aparato | O9: Incompleto
B10: Litio_Cloruro_de_Tionilo | F10: Litio_Cloruro_de_Tionilo | H10: =I10&J10&K10&L10&M10&N10 -> SíLitio_MetalEn el aparato | I10: Sí | J10: Litio_Metal | K10: En el aparato | O10: Completo
B11: _LR44_ | F11: _LR44_ | H11: =I11&J11&K11&L11&M11&N11 -> SíIon_litioCon el equipo | I11: Sí | J11: Ion_litio | K11: Con el equipo | O11: Incompleto
B12: Alcalina | F12: Alcalina | H12: =I12&J12&K12&L12&M12&N12 -> SíLitio_MetalCon el equipo | I12: Sí | J12: Litio_Metal | K12: Con el equipo | O12: Completo
B13: Carbono_zinc | F13: Carbono_zinc | H13: =I13&J13&K13&L13&M13&N13 -> SíIon_litioIndependiente | I13: Sí | J13: Ion_litio | K13: Independiente | O13: Incompleto
B14: _CR2032_ | F14: _CR2032_ | H14: =I14&J14&K14&L14&M14&N14 -> SíLitio_MetalIndependiente | I14: Sí | J14: Litio_Metal | K14: Independiente | O14: Completo
B15: Plomo_ácido | F15: Plomo_ácido | H15: =I15&J15&K15&L15&M15&N15 -> #REF! | I15: Sí | J15: Ion_litio | M15: =IF('Ficha de exención para baterías'!$P$13>0,'Ficha de exención para baterías'!$P$13," ") -> #REF! | O15: Incompleto
B16: Plomo_calcio | F16: Plomo_calcio | H16: =I16&J16&K16&L16&M16&N16 -> SíIon_litio | I16: Sí | J16: Ion_litio | O16: Incompleto
B17: Níquel_cadmio | F17: Níquel_cadmio | H17: =I17&J17&K17&L17&M17&N17 -> SíLitio_Metal | I17: Sí | J17: Litio_Metal | O17: Incompleto
B18: Níquel_metal_hidruro | F18: Níquel_metal_hidruro | H18: =I18&J18&K18&L18&M18&N18 -> SíPlomo_ácidoEn el aparatoNo derramable | I18: Sí | J18: Plomo_ácido | K18: En el aparato | N18: No derramable | O18: Completo
B19: Óxido_de_plata | F19: Óxido_de_plata | H19: =I19&J19&K19&L19&M19&N19 -> SíPlomo_ácidoEn el aparatoDerramable | I19: Sí | J19: Plomo_ácido | K19: En el aparato | N19: Derramable | O19: Completo
B20: Zinc | F20: Zinc | H20: =I20&J20&K20&L20&M20&N20 -> SíPlomo_ácido | I20: Sí | J20: Plomo_ácido | O20: Incompleto
B21: Zinc_aire | F21: Zinc_aire | H21: =I21&J21&K21&L21&M21&N21 -> SíPlomo_calcioEn el aparatoNo derramable | I21: Sí | J21: Plomo_calcio | K21: En el aparato | N21: No derramable | O21: Completo
B22: Zinc_carbono | F22: Zinc_carbono | H22: =I22&J22&K22&L22&M22&N22 -> SíPlomo_calcioEn el aparatoDerramable | I22: Sí | J22: Plomo_calcio | K22: En el aparato | N22: Derramable | O22: Completo
H23: =I23&J23&K23&L23&M23&N23 -> SíPlomo_calcio | I23: Sí | J23: Plomo_calcio | O23: Incompleto
H24: =I24&J24&K24&L24&M24&N24 -> SíLitio_Metal | I24: Sí | J24: Litio_Metal | O24: Incompleto
H25: =I25&J25&K25&L25&M25&N25 -> SíPolímero_de_litioEn el aparato | I25: Sí | J25: Polímero_de_litio | K25: En el aparato | O25: Incompleto
A26: ! | H26: =I26&J26&K26&L26&M26&N26 -> SíPolímero_de_litioCon el equipo | I26: Sí | J26: Polímero_de_litio | K26: Con el equipo | O26: Incompleto
A27: @ | H27: =I27&J27&K27&L27&M27&N27 -> SíPolímero_de_litioIndependiente | I27: Sí | J27: Polímero_de_litio | K27: Independiente | O27: Incompleto
A28: # | H28: =I28&J28&K28&L28&M28&N28 -> #REF! | I28: Sí | J28: Polímero_de_litio | M28: =IF('Ficha de exención para baterías'!$P$13>0,'Ficha de exención para baterías'!$P$13," ") -> #REF! | O28: Incompleto
A29: $ | H29: =I29&J29&K29&L29&M29&N29 -> SíPolímero_de_litio | I29: Sí | J29: Polímero_de_litio | O29: Incompleto
A30: % | H30: =I30&J30&K30&L30&M30&N30 -> SíZinc | I30: Sí | J30: Zinc | O30: Completo
A31: ^ | H31: =I31&J31&K31&L31&M31&N31 -> NoAlcalina | I31: No | J31: Alcalina | O31: Incompleto
A32: & | H32: =I32&J32&K32&L32&M32&N32 -> NoNíquel_metal_hidruro | I32: No | J32: Níquel_metal_hidruro | O32: Incompleto
A33: * | H33: =I33&J33&K33&L33&M33&N33 -> NoNíquel_cadmio | I33: No | J33: Níquel_cadmio | O33: Incompleto
H34: =I34&J34&K34&L34&M34&N34 -> NoZinc_carbono | I34: No | J34: Zinc_carbono | O34: Incompleto
H35: =I35&J35&K35&L35&M35&N35 -> NoZinc_aire | I35: No | J35: Zinc_aire | O35: Incompleto
H36: =I36&J36&K36&L36&M36&N36 -> NoÓxido_de_plata | I36: No | J36: Óxido_de_plata | O36: Incompleto
H37: =I37&J37&K37&L37&M37&N37 -> #REF! | I37: No | J37: Ion_litio | K37: En el aparato | M37: =IF('Ficha de exención para baterías'!$P$13>0,'Ficha de exención para baterías'!$P$13," ") -> #REF! | O37: Incompleto
H38: =I38&J38&K38&L38&M38&N38 -> NoIon_litioEn el aparato | I38: No | J38: Ion_litio | K38: En el aparato | O38: Incompleto
H39: =I39&J39&K39&L39&M39&N39 -> NoLitio_MetalEn el aparato | I39: No | J39: Litio_Metal | K39: En el aparato | O39: Incompleto
H40: =I40&J40&K40&L40&M40&N40 -> NoIon_litioCon el equipo | I40: No | J40: Ion_litio | K40: Con el equipo | O40: Incompleto
...

Sheet Fórmula 2
A4: _18650_ | C4: Polímero_de_litio | E4: Plomo_ácido | K4: Una_sola_celda
A5: Una_sola_celda | C5: Una_sola_celda | E5: Derramable | K5: WH <= 20
A6: Varias_celdas | C6: Varias_celdas | E6: No derramable | K6: WH > 20
A8: Óxido_cobalto_Litio | C8: Titanato_de_litio | E8: Plomo_calcio | K8: Varias_celdas
A9: Una_sola_celda | C9: Una_sola_celda | E9: Derramable | K9: WH <= 100
A10: Varias_celdas | C10: Varias_celdas | E10: No derramable | K10: 101 - 300 WH
K11: WH > 300
A12: Ion_litio
A13: Una_sola_celda
A14: Varias_celdas
A16: Litio_ferrofosfato
A17: Una_sola_celda
A18: Varias_celdas | E18: Battery Packaging ON/OFF | G18: Spillability | I18: ASIN/Title
E19: =OR('Ficha de exención para baterías'!M13="_18650_",'Ficha de exención para baterías'!M13="Óxido_cobalto_Litio",'Ficha de exención para baterías'!M13="Ion_litio",'Ficha de exención para baterías'!M13="Litio_ferrofosfato",'Ficha de exención para baterías'!M13="Óxido_de_cobalto_de_manganeso_y_litio",'Ficha de exención para baterías'!M13="Polímero_de_litio",'Ficha de exención para baterías'!M13="Titanato_de_litio",'Ficha de exención para baterías'!M13="Litio_Metal",'Ficha de exención para baterías'!M13="_CR2032_",'Ficha de exención para baterías'!M13="Litio_Cloruro_de_Tionilo",'Ficha de exención para baterías'!M13="Plomo_ácido",'Ficha de exención para baterías'!M13="Plomo_calcio") -> #REF! | G19: =OR('Ficha de exención para baterías'!M13="Plomo_ácido",'Ficha de exención para baterías'!M13="Plomo_calcio") -> #REF! | I19: =OR(LEN('Ficha de exención para baterías'!K13)>0) -> #REF!
A20: Óxido_de_cobalto_de_manganeso_y_litio | E20: =OR('Ficha de exención para baterías'!M14="_18650_",'Ficha de exención para baterías'!M14="Óxido_cobalto_Litio",'Ficha de exención para baterías'!M14="Ion_litio",'Ficha de exención para baterías'!M14="Litio_ferrofosfato",'Ficha de exención para baterías'!M14="Óxido_de_cobalto_de_manganeso_y_litio",'Ficha de exención para baterías'!M14="Polímero_de_litio",'Ficha de exención para baterías'!M14="Titanato_de_litio",'Ficha de exención para baterías'!M14="Litio_Metal",'Ficha de exención para baterías'!M14="_CR2032_",'Ficha de exención para baterías'!M14="Litio_Cloruro_de_Tionilo",'Ficha de exención para baterías'!M14="Plomo_ácido",'Ficha de exención para baterías'!M14="Plomo_calcio") -> #REF! | G20: =OR('Ficha de exención para baterías'!M14="Plomo_ácido",'Ficha de exención para baterías'!M14="Plomo_calcio") -> #REF! | I20: =OR(LEN('Ficha de exención para baterías'!K14)>0) -> #REF!
A21: Una_sola_celda | E21: =OR('Ficha de exención para baterías'!M15="_18650_",'Ficha de exención para baterías'!M15="Óxido_cobalto_Litio",'Ficha de exención para baterías'!M15="Ion_litio",'Ficha de exención para baterías'!M15="Litio_ferrofosfato",'Ficha de exención para baterías'!M15="Óxido_de_cobalto_de_manganeso_y_litio",'Ficha de exención para baterías'!M15="Polímero_de_litio",'Ficha de exención para baterías'!M15="Titanato_de_litio",'Ficha de exención para baterías'!M15="Litio_Metal",'Ficha de exención para baterías'!M15="_CR2032_",'Ficha de exención para baterías'!M15="Litio_Cloruro_de_Tionilo",'Ficha de exención para baterías'!M15="Plomo_ácido",'Ficha de exención para baterías'!M15="Plomo_calcio") -> #REF! | G21: =OR('Ficha de exención para baterías'!M15="Plomo_ácido",'Ficha de exención para baterías'!M15="Plomo_calcio") -> #REF! | I21: =OR(LEN('Ficha de exención para baterías'!K15)>0) -> #REF!
A22: Varias_celdas | E22: =OR('Ficha de exención para baterías'!M16="_18650_",'Ficha de exención para baterías'!M16="Óxido_cobalto_Litio",'Ficha de exención para baterías'!M16="Ion_litio",'Ficha de exención para baterías'!M16="Litio_ferrofosfato",'Ficha de exención para baterías'!M16="Óxido_de_cobalto_de_manganeso_y_litio",'Ficha de exención para baterías'!M16="Polímero_de_litio",'Ficha de exención para baterías'!M16="Titanato_de_litio",'Ficha de exención para baterías'!M16="Litio_Metal",'Ficha de exención para baterías'!M16="_CR2032_",'Ficha de exención para baterías'!M16="Litio_Cloruro_de_Tionilo",'Ficha de exención para baterías'!M16="Plomo_ácido",'Ficha de exención para baterías'!M16="Plomo_calcio") -> #REF! | G22: =OR('Ficha de exención para baterías'!M16="Plomo_ácido",'Ficha de exención para baterías'!M16="Plomo_calcio") -> #REF! | I22: =OR(LEN('Ficha de exención para baterías'!K16)>0) -> #REF!
E23: =OR('Ficha de exención para baterías'!M17="_18650_",'Ficha de exención para baterías'!M17="Óxido_cobalto_Litio",'Ficha de exención para baterías'!M17="Ion_litio",'Ficha de exención para baterías'!M17="Litio_ferrofosfato",'Ficha de exención para baterías'!M17="Óxido_de_cobalto_de_manganeso_y_litio",'Ficha de exención para baterías'!M17="Polímero_de_litio",'Ficha de exención para baterías'!M17="Titanato_de_litio",'Ficha de exención para baterías'!M17="Litio_Metal",'Ficha de exención para baterías'!M17="_CR2032_",'Ficha de exención para baterías'!M17="Litio_Cloruro_de_Tionilo",'Ficha de exención para baterías'!M17="Plomo_ácido",'Ficha de exención para baterías'!M17="Plomo_calcio") -> #REF! | G23: =OR('Ficha de exención para baterías'!M17="Plomo_ácido",'Ficha de exención para baterías'!M17="Plomo_calcio") -> #REF! | I23: =OR(LEN('Ficha de exención para baterías'!K17)>0) -> #REF!
E24: =OR('Ficha de exención para baterías'!M18="_18650_",'Ficha de exención para baterías'!M18="Óxido_cobalto_Litio",'Ficha de exención para baterías'!M18="Ion_litio",'Ficha de exención para baterías'!M18="Litio_ferrofosfato",'Ficha de exención para baterías'!M18="Óxido_de_cobalto_de_manganeso_y_litio",'Ficha de exención para baterías'!M18="Polímero_de_litio",'Ficha de exención para baterías'!M18="Titanato_de_litio",'Ficha de exención para baterías'!M18="Litio_Metal",'Ficha de exención para baterías'!M18="_CR2032_",'Ficha de exención para baterías'!M18="Litio_Cloruro_de_Tionilo",'Ficha de exención para baterías'!M18="Plomo_ácido",'Ficha de exención para baterías'!M18="Plomo_calcio") -> #REF! | G24: =OR('Ficha de exención para baterías'!M18="Plomo_ácido",'Ficha de exención para baterías'!M18="Plomo_calcio") -> #REF! | I24: =OR(LEN('Ficha de exención para baterías'!K18)>0) -> #REF!
A25: Sí | B25: No | E25: =OR('Ficha de exención para baterías'!M19="_18650_",'Ficha de exención para baterías'!M19="Óxido_cobalto_Litio",'Ficha de exención para baterías'!M19="Ion_litio",'Ficha de exención para baterías'!M19="Litio_ferrofosfato",'Ficha de exención para baterías'!M19="Óxido_de_cobalto_de_manganeso_y_litio",'Ficha de exención para baterías'!M19="Polímero_de_litio",'Ficha de exención para baterías'!M19="Titanato_de_litio",'Ficha de exención para baterías'!M19="Litio_Metal",'Ficha de exención para baterías'!M19="_CR2032_",'Ficha de exención para baterías'!M19="Litio_Cloruro_de_Tionilo",'Ficha de exención para baterías'!M19="Plomo_ácido",'Ficha de exención para baterías'!M19="Plomo_calcio") -> #REF! | G25: =OR('Ficha de exención para baterías'!M19="Plomo_ácido",'Ficha de exención para baterías'!M19="Plomo_calcio") -> #REF! | I25: =OR(LEN('Ficha de exención para baterías'!K19)>0) -> #REF!
A26: _18650_ | C26: _18650_ | E26: =OR('Ficha de exención para baterías'!M20="_18650_",'Ficha de exención para baterías'!M20="Óxido_cobalto_Litio",'Ficha de exención para baterías'!M20="Ion_litio",'Ficha de exención para baterías'!M20="Litio_ferrofosfato",'Ficha de exención para baterías'!M20="Óxido_de_cobalto_de_manganeso_y_litio",'Ficha de exención para baterías'!M20="Polímero_de_litio",'Ficha de exención para baterías'!M20="Titanato_de_litio",'Ficha de exención para baterías'!M20="Litio_Metal",'Ficha de exención para baterías'!M20="_CR2032_",'Ficha de exención para baterías'!M20="Litio_Cloruro_de_Tionilo",'Ficha de exención para baterías'!M20="Plomo_ácido",'Ficha de exención para baterías'!M20="Plomo_calcio") -> #REF! | G26: =OR('Ficha de exención para baterías'!M20="Plomo_ácido",'Ficha de exención para baterías'!M20="Plomo_calcio") -> #REF! | I26: =OR(LEN('Ficha de exención para baterías'!K20)>0) -> #REF!
A27: Óxido_cobalto_Litio | C27: Óxido_de_litio_y_cobalto | E27: =OR('Ficha de exención para baterías'!M21="_18650_",'Ficha de exención para baterías'!M21="Óxido_cobalto_Litio",'Ficha de exención para baterías'!M21="Ion_litio",'Ficha de exención para baterías'!M21="Litio_ferrofosfato",'Ficha de exención para baterías'!M21="Óxido_de_cobalto_de_manganeso_y_litio",'Ficha de exención para baterías'!M21="Polímero_de_litio",'Ficha de exención para baterías'!M21="Titanato_de_litio",'Ficha de exención para baterías'!M21="Litio_Metal",'Ficha de exención para baterías'!M21="_CR2032_",'Ficha de exención para baterías'!M21="Litio_Cloruro_de_Tionilo",'Ficha de exención para baterías'!M21="Plomo_ácido",'Ficha de exención para baterías'!M21="Plomo_calcio") -> #REF! | G27: =OR('Ficha de exención para baterías'!M21="Plomo_ácido",'Ficha de exención para baterías'!M21="Plomo_calcio") -> #REF! | I27: =OR(LEN('Ficha de exención para baterías'!K21)>0) -> #REF!
A28: Ion_litio | C28: Ion_litio | E28: =OR('Ficha de exención para baterías'!M22="_18650_",'Ficha de exención para baterías'!M22="Óxido_cobalto_Litio",'Ficha de exención para baterías'!M22="Ion_litio",'Ficha de exención para baterías'!M22="Litio_ferrofosfato",'Ficha de exención para baterías'!M22="Óxido_de_cobalto_de_manganeso_y_litio",'Ficha de exención para baterías'!M22="Polímero_de_litio",'Ficha de exención para baterías'!M22="Titanato_de_litio",'Ficha de exención para baterías'!M22="Litio_Metal",'Ficha de exención para baterías'!M22="_CR2032_",'Ficha de exención para baterías'!M22="Litio_Cloruro_de_Tionilo",'Ficha de exención para baterías'!M22="Plomo_ácido",'Ficha de exención para baterías'!M22="Plomo_calcio") -> #REF! | G28: =OR('Ficha de exención para baterías'!M22="Plomo_ácido",'Ficha de exención para baterías'!M22="Plomo_calcio") -> #REF! | I28: =OR(LEN('Ficha de exención para baterías'!K22)>0) -> #REF!
A29: Litio_ferrofosfato | C29: Fosfato_de_hierro_y_litio | E29: =OR('Ficha de exención para baterías'!M23="_18650_",'Ficha de exención para baterías'!M23="Óxido_cobalto_Litio",'Ficha de exención para baterías'!M23="Ion_litio",'Ficha de exención para baterías'!M23="Litio_ferrofosfato",'Ficha de exención para baterías'!M23="Óxido_de_cobalto_de_manganeso_y_litio",'Ficha de exención para baterías'!M23="Polímero_de_litio",'Ficha de exención para baterías'!M23="Titanato_de_litio",'Ficha de exención para baterías'!M23="Litio_Metal",'Ficha de exención para baterías'!M23="_CR2032_",'Ficha de exención para baterías'!M23="Litio_Cloruro_de_Tionilo",'Ficha de exención para baterías'!M23="Plomo_ácido",'Ficha de exención para baterías'!M23="Plomo_calcio") -> #REF! | G29: =OR('Ficha de exención para baterías'!M23="Plomo_ácido",'Ficha de exención para baterías'!M23="Plomo_calcio") -> #REF! | I29: =OR(LEN('Ficha de exención para baterías'!K23)>0) -> #REF!
A30: Óxido_de_cobalto_de_manganeso_y_litio | C30: Óxido_de_litio_níquel_manganeso_y_cobalto | E30: =OR('Ficha de exención para baterías'!M24="_18650_",'Ficha de exención para baterías'!M24="Óxido_cobalto_Litio",'Ficha de exención para baterías'!M24="Ion_litio",'Ficha de exención para baterías'!M24="Litio_ferrofosfato",'Ficha de exención para baterías'!M24="Óxido_de_cobalto_de_manganeso_y_litio",'Ficha de exención para baterías'!M24="Polímero_de_litio",'Ficha de exención para baterías'!M24="Titanato_de_litio",'Ficha de exención para baterías'!M24="Litio_Metal",'Ficha de exención para baterías'!M24="_CR2032_",'Ficha de exención para baterías'!M24="Litio_Cloruro_de_Tionilo",'Ficha de exención para baterías'!M24="Plomo_ácido",'Ficha de exención para baterías'!M24="Plomo_calcio") -> #REF! | G30: =OR('Ficha de exención para baterías'!M24="Plomo_ácido",'Ficha de exención para baterías'!M24="Plomo_calcio") -> #REF! | I30: =OR(LEN('Ficha de exención para baterías'!K24)>0) -> #REF!
A31: Polímero_de_litio | C31: Polímero_de_litio | E31: =OR('Ficha de exención para baterías'!M25="_18650_",'Ficha de exención para baterías'!M25="Óxido_cobalto_Litio",'Ficha de exención para baterías'!M25="Ion_litio",'Ficha de exención para baterías'!M25="Litio_ferrofosfato",'Ficha de exención para baterías'!M25="Óxido_de_cobalto_de_manganeso_y_litio",'Ficha de exención para baterías'!M25="Polímero_de_litio",'Ficha de exención para baterías'!M25="Titanato_de_litio",'Ficha de exención para baterías'!M25="Litio_Metal",'Ficha de exención para baterías'!M25="_CR2032_",'Ficha de exención para baterías'!M25="Litio_Cloruro_de_Tionilo",'Ficha de exención para baterías'!M25="Plomo_ácido",'Ficha de exención para baterías'!M25="Plomo_calcio") -> #REF! | G31: =OR('Ficha de exención para baterías'!M25="Plomo_ácido",'Ficha de exención para baterías'!M25="Plomo_calcio") -> #REF! | I31: =OR(LEN('Ficha de exención para baterías'!K25)>0) -> #REF!
A32: Titanato_de_litio | C32: Titanato_de_litio | E32: =OR('Ficha de exención para baterías'!M26="_18650_",'Ficha de exención para baterías'!M26="Óxido_cobalto_Litio",'Ficha de exención para baterías'!M26="Ion_litio",'Ficha de exención para baterías'!M26="Litio_ferrofosfato",'Ficha de exención para baterías'!M26="Óxido_de_cobalto_de_manganeso_y_litio",'Ficha de exención para baterías'!M26="Polímero_de_litio",'Ficha de exención para baterías'!M26="Titanato_de_litio",'Ficha de exención para baterías'!M26="Litio_Metal",'Ficha de exención para baterías'!M26="_CR2032_",'Ficha de exención para baterías'!M26="Litio_Cloruro_de_Tionilo",'Ficha de exención para baterías'!M26="Plomo_ácido",'Ficha de exención para baterías'!M26="Plomo_calcio") -> #REF! | G32: =OR('Ficha de exención para baterías'!M26="Plomo_ácido",'Ficha de exención para baterías'!M26="Plomo_calcio") -> #REF! | I32: =OR(LEN('Ficha de exención para baterías'!K26)>0) -> #REF!
A33: Litio_Metal | C33: Metal_de_litio | E33: =OR('Ficha de exención para baterías'!M27="_18650_",'Ficha de exención para baterías'!M27="Óxido_cobalto_Litio",'Ficha de exención para baterías'!M27="Ion_litio",'Ficha de exención para baterías'!M27="Litio_ferrofosfato",'Ficha de exención para baterías'!M27="Óxido_de_cobalto_de_manganeso_y_litio",'Ficha de exención para baterías'!M27="Polímero_de_litio",'Ficha de exención para baterías'!M27="Titanato_de_litio",'Ficha de exención para baterías'!M27="Litio_Metal",'Ficha de exención para baterías'!M27="_CR2032_",'Ficha de exención para baterías'!M27="Litio_Cloruro_de_Tionilo",'Ficha de exención para baterías'!M27="Plomo_ácido",'Ficha de exención para baterías'!M27="Plomo_calcio") -> #REF! | G33: =OR('Ficha de exención para baterías'!M27="Plomo_ácido",'Ficha de exención para baterías'!M27="Plomo_calcio") -> #REF! | I33: =OR(LEN('Ficha de exención para baterías'!K27)>0) -> #REF!
A34: Litio_Cloruro_de_Tionilo | C34: Cloruro_de_tionilo_de_litio | E34: =OR('Ficha de exención para baterías'!M28="_18650_",'Ficha de exención para baterías'!M28="Óxido_cobalto_Litio",'Ficha de exención para baterías'!M28="Ion_litio",'Ficha de exención para baterías'!M28="Litio_ferrofosfato",'Ficha de exención para baterías'!M28="Óxido_de_cobalto_de_manganeso_y_litio",'Ficha de exención para baterías'!M28="Polímero_de_litio",'Ficha de exención para baterías'!M28="Titanato_de_litio",'Ficha de exención para baterías'!M28="Litio_Metal",'Ficha de exención para baterías'!M28="_CR2032_",'Ficha de exención para baterías'!M28="Litio_Cloruro_de_Tionilo",'Ficha de exención para baterías'!M28="Plomo_ácido",'Ficha de exención para baterías'!M28="Plomo_calcio") -> #REF! | G34: =OR('Ficha de exención para baterías'!M28="Plomo_ácido",'Ficha de exención para baterías'!M28="Plomo_calcio") -> #REF! | I34: =OR(LEN('Ficha de exención para baterías'!K28)>0) -> #REF!
A35: _LR44_ | C35: _LR44_ | E35: =OR('Ficha de exención para baterías'!M29="_18650_",'Ficha de exención para baterías'!M29="Óxido_cobalto_Litio",'Ficha de exención para baterías'!M29="Ion_litio",'Ficha de exención para baterías'!M29="Litio_ferrofosfato",'Ficha de exención para baterías'!M29="Óxido_de_cobalto_de_manganeso_y_litio",'Ficha de exención para baterías'!M29="Polímero_de_litio",'Ficha de exención para baterías'!M29="Titanato_de_litio",'Ficha de exención para baterías'!M29="Litio_Metal",'Ficha de exención para baterías'!M29="_CR2032_",'Ficha de exención para baterías'!M29="Litio_Cloruro_de_Tionilo",'Ficha de exención para baterías'!M29="Plomo_ácido",'Ficha de exención para baterías'!M29="Plomo_calcio") -> #REF! | G35: =OR('Ficha de exención para baterías'!M29="Plomo_ácido",'Ficha de exención para baterías'!M29="Plomo_calcio") -> #REF! | I35: =OR(LEN('Ficha de exención para baterías'!K29)>0) -> #REF!
A36: Alcalina | C36: Alcalina | E36: =OR('Ficha de exención para baterías'!M30="_18650_",'Ficha de exención para baterías'!M30="Óxido_cobalto_Litio",'Ficha de exención para baterías'!M30="Ion_litio",'Ficha de exención para baterías'!M30="Litio_ferrofosfato",'Ficha de exención para baterías'!M30="Óxido_de_cobalto_de_manganeso_y_litio",'Ficha de exención para baterías'!M30="Polímero_de_litio",'Ficha de exención para baterías'!M30="Titanato_de_litio",'Ficha de exención para baterías'!M30="Litio_Metal",'Ficha de exención para baterías'!M30="_CR2032_",'Ficha de exención para baterías'!M30="Litio_Cloruro_de_Tionilo",'Ficha de exención para baterías'!M30="Plomo_ácido",'Ficha de exención para baterías'!M30="Plomo_calcio") -> #REF! | G36: =OR('Ficha de exención para baterías'!M30="Plomo_ácido",'Ficha de exención para baterías'!M30="Plomo_calcio") -> #REF! | I36: =OR(LEN('Ficha de exención para baterías'!K30)>0) -> #REF!
A37: Carbono_zinc | C37: Carbono_zinc | E37: =OR('Ficha de exención para baterías'!M31="_18650_",'Ficha de exención para baterías'!M31="Óxido_cobalto_Litio",'Ficha de exención para baterías'!M31="Ion_litio",'Ficha de exención para baterías'!M31="Litio_ferrofosfato",'Ficha de exención para baterías'!M31="Óxido_de_cobalto_de_manganeso_y_litio",'Ficha de exención para baterías'!M31="Polímero_de_litio",'Ficha de exención para baterías'!M31="Titanato_de_litio",'Ficha de exención para baterías'!M31="Litio_Metal",'Ficha de exención para baterías'!M31="_CR2032_",'Ficha de exención para baterías'!M31="Litio_Cloruro_de_Tionilo",'Ficha de exención para baterías'!M31="Plomo_ácido",'Ficha de exención para baterías'!M31="Plomo_calcio") -> #REF! | G37: =OR('Ficha de exención para baterías'!M31="Plomo_ácido",'Ficha de exención para baterías'!M31="Plomo_calcio") -> #REF! | I37: =OR(LEN('Ficha de exención para baterías'!K31)>0) -> #REF!
A38: _CR2032_ | C38: _CR2032_ | E38: =OR('Ficha de exención para baterías'!M32="_18650_",'Ficha de exención para baterías'!M32="Óxido_cobalto_Litio",'Ficha de exención para baterías'!M32="Ion_litio",'Ficha de exención para baterías'!M32="Litio_ferrofosfato",'Ficha de exención para baterías'!M32="Óxido_de_cobalto_de_manganeso_y_litio",'Ficha de exención para baterías'!M32="Polímero_de_litio",'Ficha de exención para baterías'!M32="Titanato_de_litio",'Ficha de exención para baterías'!M32="Litio_Metal",'Ficha de exención para baterías'!M32="_CR2032_",'Ficha de exención para baterías'!M32="Litio_Cloruro_de_Tionilo",'Ficha de exención para baterías'!M32="Plomo_ácido",'Ficha de exención para baterías'!M32="Plomo_calcio") -> #REF! | G38: =OR('Ficha de exención para baterías'!M32="Plomo_ácido",'Ficha de exención para baterías'!M32="Plomo_calcio") -> #REF! | I38: =OR(LEN('Ficha de exención para baterías'!K32)>0) -> #REF!
A39: Plomo_ácido | C39: Plomo_ácido
A40: Plomo_calcio | C40: Plomo_calcio
A41: Níquel_cadmio | C41: Níquel_cadmio
A42: Níquel_metal_hidruro | C42: Níquel_metal_hidruro
A43: Óxido_de_plata | C43: Óxido_de_plata
A44: Zinc | C44: Zinc
A45: Zinc_aire | C45: Aire_de_zinc
...

Sheet Productos IQ TECH
A1: ASIN | B1: Nombre del Producto
A2: B0FBZFCL6Z | B2: IQ TECH Centro de Desayunos 3 en 1 1050 W | Tostador Horno + Cafetera + Plancha Antiadherente | Compacto, Temporizador, Fácil Limpieza
A3: B0FBT75NTR | B3: IQ Tech Cargador inalámbrico Plegable 3 en 1, Almohadilla magnética de Carga inalámbrica rápida, Compatible con iPhone 15/14/13/12 Series, Apple Watch, AirPods Pro (Adaptador no Incluido)
A4: B0FBQCMN4K | B4: IQ TECH Ventilador en la pared, ventilador de calentador pequeño con visualización digital, control remoto portátil para habitación, cocina, oficina, recámara Instalacion DOBLE FUNCION
A5: B0FGLL5RGB | B5: IQ Tech Bandeja de Brazo para sofá, con Clip en la Mesa Lateral, Mesa Plegable con Soporte para teléfono de 360°, bandejas de Comida para Comer/Bebidas/Aperitivos/Control Remoto
A6: B0FGKMQ5QW | B6: IQ Tech Espejo de Maquillaje con Luz LED, Espejo de Maquillaje Portátil con Brillo LED, Pantalla táctil, por USB, Espejo de Maquillaje Portátil Ultra Delgado Iluminado (Rosa)
A7: B0FGKTDTY9 | B7: IQ TECH Paquete de 3 luces hexagonales, paneles de pared RGB con control remoto y táctil, paneles de luz LED para sala de estar, recámara, decoración de sala de juegos
A8: B0FGKJ45HS | B8: IQ Tech Espejo de Maquillaje para Tocador Hollywood con Luz - Espejo con Luz para Makeup Hollywood Vintage, con 9 Focos LED Regulables de Blanca, Cálida y Neutra, Conexión USB (Blanco, 35.5x30.5 CM)
A9: B0GDRVJLTW | B9: IQ TECH- Masajeador térmico Bionic, masajeador Shiatsu portátil inalámbrico, cuello y espalda, masaje eléctrico de amasado 4D, diseño simulado de manos humanas para aliviar el dolor y relajación
A10: B0G88JK9SC | B10: IQ TECH Licuadora Portatil con 2 vasos Tazas, Mini Licuadora de 700ml 500W Licuadora Personal con Cuchillas Pro 304 Acero Inoxidable Extractoras de Nutrientes, para Smoothies, Batidos y Congeladas
A11: B0GXLFSD3K | B11: IQ TECH 1400W Donut Maker, Mini Donut Maker para 12 Mini Donuts, Antiadherente, Regulación automática de la temperatura, Libre de BPA
A12: B0GXLGPHRY | B12: IQ TECH Exprimidor de verduras y frutas de 800 W, con rendimiento de zumo optimizado, gran orificio de llenado de 65 mm, 2 niveles de velocidad, fácil de limpiar, negro/acero inoxidable
... A36: B0H2NHKK4G | B36: IQ-TECH 8 en 1 Esterilizador de Vapor de Biberones, Esterilización Biberones, Calentador de Biberones con Funciones de Descongelar, Esterilizar, Calentar Leche y Calentar Alimentos (Gris)

Sheet Copia de EKT
